Workbook

Sheet HUONG_DAN
A1: HƯỚNG DẪN THỰC THI TEST CASE
A2: Workbook chỉ dành cho UC-COM-01 đến UC-COM-12
A3: Mục | B3: Hướng dẫn | C3: Bắt buộc | D3: Ghi chú
A4: Trước khi test | B4: Ghi Build/Environment tại sheet TONG_QUAN; chuẩn bị account và dữ liệu theo TEST_DATA. | C4: Có | D4: Không dùng dữ liệu production.
A5: Thực thi | B5: Mở sheet UC tương ứng, lọc Priority/Status, làm lần lượt các bước và ghi Actual Result. | C5: Có | D5: P0 trước, sau đó P1 và P2.
A6: Status | B6: Not Run: chưa chạy; Pass: đúng; Fail: sai; Blocked: không thể chạy; N/A: không áp dụng. | C6: Có | D6: Fail/Blocked phải có evidence.
A7: Khi Fail | B7: Chọn Severity, nhập Defect ID, request/response đã che token/OTP và Evidence/Link. | C7: Có | D7: Không đưa secret vào ticket.
A8: Retest | B8: Giữ nguyên Test Case ID, cập nhật Actual Result/Status/Ngày chạy và ghi lịch sử trong Ghi chú. | C8: Có | D8: Không xóa bằng chứng lần chạy cũ.
A9: Nguồn kỳ vọng | B9: Expected Result lấy từ test plan và implementation hiện tại; đối chiếu Notion trước sign-off. | C9: Có | D9: Các điểm mở nằm trong test plan.

Sheet TONG_QUAN
A1: TỔNG QUAN THỰC THI
A2: Sinh ngày 30/09/2026 từ COMMON_SERVICES_TEST_PLAN.md
A3: UC ID | B3: Tên use case | C3: Tổng TC | D3: P0 | E3: P1 | F3: P2 | G3: Pass | H3: Fail | I3: Blocked | J3: Not Run | K3: % Pass
A4: UC-COM-01 | B4: Đăng ký và xác thực tài khoản | C4: 14 | D4: 8 | E4: 6 | F4: 0 | G4: =COUNTIF('COM-01'!$O:$O,"Pass") | H4: =COUNTIF('COM-01'!$O:$O,"Fail") | I4: =COUNTIF('COM-01'!$O:$O,"Blocked") | J4: =COUNTIF('COM-01'!$O:$O,"Not Run") | K4: =IF(C4=0,0,G4/C4)
A5: UC-COM-02 | B5: Gửi yêu cầu tham gia doanh nghiệp | C5: 14 | D5: 7 | E5: 7 | F5: 0 | G5: =COUNTIF('COM-02'!$O:$O,"Pass") | H5: =COUNTIF('COM-02'!$O:$O,"Fail") | I5: =COUNTIF('COM-02'!$O:$O,"Blocked") | J5: =COUNTIF('COM-02'!$O:$O,"Not Run") | K5: =IF(C5=0,0,G5/C5)
A6: UC-COM-03 | B6: Đăng nhập | C6: 13 | D6: 8 | E6: 5 | F6: 0 | G6: =COUNTIF('COM-03'!$O:$O,"Pass") | H6: =COUNTIF('COM-03'!$O:$O,"Fail") | I6: =COUNTIF('COM-03'!$O:$O,"Blocked") | J6: =COUNTIF('COM-03'!$O:$O,"Not Run") | K6: =IF(C6=0,0,G6/C6)
A7: UC-COM-04 | B7: Đăng xuất | C7: 7 | D7: 5 | E7: 2 | F7: 0 | G7: =COUNTIF('COM-04'!$O:$O,"Pass") | H7: =COUNTIF('COM-04'!$O:$O,"Fail") | I7: =COUNTIF('COM-04'!$O:$O,"Blocked") | J7: =COUNTIF('COM-04'!$O:$O,"Not Run") | K7: =IF(C7=0,0,G7/C7)
A8: UC-COM-05 | B8: Quên và đặt lại mật khẩu | C8: 11 | D8: 7 | E8: 4 | F8: 0 | G8: =COUNTIF('COM-05'!$O:$O,"Pass") | H8: =COUNTIF('COM-05'!$O:$O,"Fail") | I8: =COUNTIF('COM-05'!$O:$O,"Blocked") | J8: =COUNTIF('COM-05'!$O:$O,"Not Run") | K8: =IF(C8=0,0,G8/C8)
A9: UC-COM-06 | B9: Đổi mật khẩu | C9: 9 | D9: 6 | E9: 3 | F9: 0 | G9: =COUNTIF('COM-06'!$O:$O,"Pass") | H9: =COUNTIF('COM-06'!$O:$O,"Fail") | I9: =COUNTIF('COM-06'!$O:$O,"Blocked") | J9: =COUNTIF('COM-06'!$O:$O,"Not Run") | K9: =IF(C9=0,0,G9/C9)
A10: UC-COM-07 | B10: Quản lý tài khoản cá nhân | C10: 12 | D10: 3 | E10: 9 | F10: 0 | G10: =COUNTIF('COM-07'!$O:$O,"Pass") | H10: =COUNTIF('COM-07'!$O:$O,"Fail") | I10: =COUNTIF('COM-07'!$O:$O,"Blocked") | J10: =COUNTIF('COM-07'!$O:$O,"Not Run") | K10: =IF(C10=0,0,G10/C10)
A11: UC-COM-08 | B11: Chuyển phạm vi làm việc | C11: 11 | D11: 6 | E11: 5 | F11: 0 | G11: =COUNTIF('COM-08'!$O:$O,"Pass") | H11: =COUNTIF('COM-08'!$O:$O,"Fail") | I11: =COUNTIF('COM-08'!$O:$O,"Blocked") | J11: =COUNTIF('COM-08'!$O:$O,"Not Run") | K11: =IF(C11=0,0,G11/C11)
A12: UC-COM-09 | B12: Xem và xử lý thông báo | C12: 12 | D12: 3 | E12: 8 | F12: 1 | G12: =COUNTIF('COM-09'!$O:$O,"Pass") | H12: =COUNTIF('COM-09'!$O:$O,"Fail") | I12: =COUNTIF('COM-09'!$O:$O,"Blocked") | J12: =COUNTIF('COM-09'!$O:$O,"Not Run") | K12: =IF(C12=0,0,G12/C12)
A13: UC-COM-10 | B13: Tìm kiếm toàn hệ thống | C13: 11 | D13: 5 | E13: 6 | F13: 0 | G13: =COUNTIF('COM-10'!$O:$O,"Pass") | H13: =COUNTIF('COM-10'!$O:$O,"Fail") | I13: =COUNTIF('COM-10'!$O:$O,"Blocked") | J13: =COUNTIF('COM-10'!$O:$O,"Not Run") | K13: =IF(C13=0,0,G13/C13)
A14: UC-COM-11 | B14: Xem việc cần xử lý | C14: 12 | D14: 3 | E14: 9 | F14: 0 | G14: =COUNTIF('COM-11'!$O:$O,"Pass") | H14: =COUNTIF('COM-11'!$O:$O,"Fail") | I14: =COUNTIF('COM-11'!$O:$O,"Blocked") | J14: =COUNTIF('COM-11'!$O:$O,"Not Run") | K14: =IF(C14=0,0,G14/C14)
A15: UC-COM-12 | B15: Sử dụng AI Assistant | C15: 16 | D15: 5 | E15: 11 | F15: 0 | G15: =COUNTIF('COM-12'!$O:$O,"Pass") | H15: =COUNTIF('COM-12'!$O:$O,"Fail") | I15: =COUNTIF('COM-12'!$O:$O,"Blocked") | J15: =COUNTIF('COM-12'!$O:$O,"Not Run") | K15: =IF(C15=0,0,G15/C15)
A16: TOTAL | B16: UC-COM-01 đến UC-COM-12 | C16: =SUM(C4:C15) | D16: =SUM(D4:D15) | E16: =SUM(E4:E15) | F16: =SUM(F4:F15) | G16: =SUM(G4:G15) | H16: =SUM(H4:H15) | I16: =SUM(I4:I15) | J16: =SUM(J4:J15) | K16: =IF(C16=0,0,G16/C16)
A18: Environment | B18: Staging
A19: Build/Commit
A20: Test cycle
A21: Người phụ trách
A22: Ngày bắt đầu/kết thúc

Sheet TEST_DATA
A1: DỮ LIỆU VÀ TÀI KHOẢN KIỂM THỬ
A2: Thay giá trị placeholder bằng credential/UUID của môi trường; không ghi mật khẩu production
A3: Mã | B3: Đối tượng | C3: Trạng thái/Quyền | D3: Doanh nghiệp/Chi nhánh | E3: Mục đích | F3: Giá trị môi trường
A4: U0 | B4: Khách chưa đăng ký | C4: Anonymous | D4: - | E4: Đăng ký
A5: U1 | B5: Tài khoản chờ xác thực | C5: INACTIVE/UNVERIFIED | D5: - | E5: OTP, pending login
A6: U2 | B6: User đã verify | C6: ACTIVE, chưa có membership | D6: - | E6: Join request/company setup
A7: U3 | B7: User toàn quyền | C7: ACTIVE, full Permission/Data Scope | D7: C1 / all branches | E7: Happy path
A8: U4 | B8: User hạn chế | C8: ACTIVE, chỉ B1 | D8: C1 / B1 | E8: Negative scope
A9: U5 | B9: User đa doanh nghiệp | C9: ACTIVE | D9: C1 + C2 | E9: Company selection/switch
A10: U6 | B10: User khóa/inactive | C10: LOCKED hoặc INACTIVE | D10: C1 | E10: Negative authentication
A11: U7 | B11: Admin duyệt | C11: COM.JOIN_REQUEST.VIEW/APPROVE | D11: C1 | E11: Duyệt/từ chối join request
A12: U8 | B12: User tenant khác | C12: ACTIVE | D12: C2 | E12: Tenant isolation/IDOR
A13: C1 | B13: Doanh nghiệp chính | C13: ACTIVE | D13: B1+B2+branch inactive | E13: Test tenant chính
A14: C2 | B14: Doanh nghiệp khác | C14: ACTIVE | D14: B3 | E14: Test cách ly tenant
A15: S1/S2 | B15: Hai login session | C15: ACTIVE | D15: Hai thiết bị/IP/User-Agent | E15: Session revocation
... A18: A1–A4 | B18: Cấu hình AI | C18: OFF/ON-no-data/success/error-timeout | D18: C1 | E18: UC-COM-12

Sheet TRACEABILITY
A1: MA TRẬN TRUY VẾT
A2: Liên kết Use Case → nguồn Notion → API → test case
A3: UC ID | B3: Tên use case | C3: Nguồn Notion | D3: API chính | E3: Số test case | F3: Test Case IDs
A4: UC-COM-01 | B4: Đăng ký và xác thực tài khoản | C4: Mở đặc tả | D4: POST /api/v1/common/auth/register/ POST /api/v1/common/auth/verify-registration/ POST /api/v1/common/auth/resend-verification/ POST /api/v1/common/auth/change-registration-email/ | E4: 14 | F4: COM01-01, COM01-02, COM01-03, COM01-04, COM01-05, COM01-06, COM01-07, COM01-08, COM01-09, COM01-10, COM01-11, COM01-12, COM01-13, COM01-14
A5: UC-COM-02 | B5: Gửi yêu cầu tham gia doanh nghiệp | C5: Mở đặc tả | D5: GET /api/v1/common/companies/search/ GET|POST /api/v1/common/join-requests/ POST /api/v1/common/join-requests/{id}/cancel/ GET /api/v1/common/company-join-requests/ POST /api/v1/common/company-join-requests/{id}/decide/ | E5: 14 | F5: COM02-01, COM02-02, COM02-03, COM02-04, COM02-05, COM02-06, COM02-07, COM02-08, COM02-09, COM02-10, COM02-11, COM02-12, COM02-13, COM02-14
A6: UC-COM-03 | B6: Đăng nhập | C6: Mở đặc tả | D6: POST /api/v1/common/auth/login/ POST /api/token/refresh/ | E6: 13 | F6: COM03-01, COM03-02, COM03-03, COM03-04, COM03-05, COM03-06, COM03-07, COM03-08, COM03-09, COM03-10, COM03-11, COM03-12, COM03-13
A7: UC-COM-04 | B7: Đăng xuất | C7: Mở đặc tả | D7: POST /api/v1/common/auth/logout/ | E7: 7 | F7: COM04-01, COM04-02, COM04-03, COM04-04, COM04-05, COM04-06, COM04-07
A8: UC-COM-05 | B8: Quên và đặt lại mật khẩu | C8: Mở đặc tả | D8: POST /api/v1/common/auth/forgot-password/ POST /api/v1/common/auth/reset-password/ | E8: 11 | F8: COM05-01, COM05-02, COM05-03, COM05-04, COM05-05, COM05-06, COM05-07, COM05-08, COM05-09, COM05-10, COM05-11
A9: UC-COM-06 | B9: Đổi mật khẩu | C9: Mở đặc tả | D9: POST /api/v1/common/auth/change-password/ | E9: 9 | F9: COM06-01, COM06-02, COM06-03, COM06-04, COM06-05, COM06-06, COM06-07, COM06-08, COM06-09
A10: UC-COM-07 | B10: Quản lý tài khoản cá nhân | C10: Mở đặc tả | D10: GET|PATCH /api/v1/common/profile/ POST /api/v1/common/profile/confirm-email/ | E10: 12 | F10: COM07-01, COM07-02, COM07-03, COM07-04, COM07-05, COM07-06, COM07-07, COM07-08, COM07-09, COM07-10, COM07-11, COM07-12
A11: UC-COM-08 | B11: Chuyển phạm vi làm việc | C11: Mở đặc tả | D11: GET /api/v1/common/scopes/ GET /api/v1/common/companies/mine/ POST /api/v1/common/companies/switch/ | E11: 11 | F11: COM08-01, COM08-02, COM08-03, COM08-04, COM08-05, COM08-06, COM08-07, COM08-08, COM08-09, COM08-10, COM08-11
A12: UC-COM-09 | B12: Xem và xử lý thông báo | C12: Mở đặc tả | D12: GET /api/v1/common/notifications/ POST /api/v1/common/notifications/{id}/{read|unread|archive|open}/ POST /api/v1/common/notifications/read-all/ GET /api/v1/common/notifications/unread-count/ | E12: 12 | F12: COM09-01, COM09-02, COM09-03, COM09-04, COM09-05, COM09-06, COM09-07, COM09-08, COM09-09, COM09-10, COM09-11, COM09-12
A13: UC-COM-10 | B13: Tìm kiếm toàn hệ thống | C13: Mở đặc tả | D13: GET /api/v1/common/search/ POST /api/v1/common/search/open/ | E13: 11 | F13: COM10-01, COM10-02, COM10-03, COM10-04, COM10-05, COM10-06, COM10-07, COM10-08, COM10-09, COM10-10, COM10-11
A14: UC-COM-11 | B14: Xem việc cần xử lý | C14: Mở đặc tả | D14: GET /api/v1/common/work-items/ GET /api/v1/common/work-items/count/ POST /api/v1/common/work-items/{id}/open/ GET /api/v1/common/work-items/{id}/history/ | E14: 12 | F14: COM11-01, COM11-02, COM11-03, COM11-04, COM11-05, COM11-06, COM11-07, COM11-08, COM11-09, COM11-10, COM11-11, COM11-12
A15: UC-COM-12 | B15: Sử dụng AI Assistant | C15: Mở đặc tả | D15: GET|POST /api/v1/common/ai-conversations/ POST /api/v1/common/ai/query/ POST /api/v1/common/ai/{id}/{confirm|feedback}/ POST /api/v1/common/ai/{id}/source/{index}/ | E15: 16 | F15: COM12-01, COM12-02, COM12-03, COM12-04, COM12-05, COM12-06, COM12-07, COM12-08, COM12-09, COM12-10, COM12-11, COM12-12, COM12-13, COM12-14, COM12-15, COM12-16

Sheet POSTMAN_CASES
A1: POSTMAN – REQUEST THỰC THI CHI TIẾT
A2: Mỗi dòng là một HTTP request. Chỉ sửa các ô màu vàng từ Status đến Evidence; request/input lấy nguyên văn từ các cột bên trái.
A3: Request ID | B3: Test Case ID | C3: UC ID | D3: Tên test case | E3: Method | F3: Request URL | G3: Tài khoản/Token | H3: Path variables | I3: Query parameters | J3: Headers | K3: Request Body | L3: Chuẩn bị dữ liệu / Cách lấy biến | M3: Expected HTTP | N3: Expected response & side effects | O3: Postman Tests | P3: Status | Q3: Actual Result | R3: Tester | S3: Ngày chạy | T3: Defect ID | U3: Evidence/Link | V3: Kiểm tra nhập liệu
A4: COM01-01 | B4: COM01-01 | C4: UC-COM-01 | D4: Đăng ký đủ dữ liệu hợp lệ và chấp nhận điều khoản | E4: POST | F4: {{base_url}}/api/v1/common/auth/register/ | G4: Không cần token (public endpoint) | H4: Các biến {{...}} trong path phải lấy từ response/seed; xem cột chuẩn bị dữ liệu. | I4: Không có | J4: Accept: application/json Content-Type: application/json | K4: { "username": "{{register_username}}", "email": "{{register_email}}", "phone": "{{register_phone}}", "display_name": "Người dùng QA", "password": "{{register_password}}", "password_confirm": "{{register_password_confirm}}", "terms_accepted": true, "terms_version": "2026-01", "privacy_version": "2026-01" } | L4: 1. Lấy challenge từ response trước đó và OTP từ email sandbox; không ghi OTP vào defect/evidence. 2. Điền UUID từ dữ liệu seed/staging; không tự đặt UUID giả nếu case yêu cầu object tồn tại. 3. Đối chiếu actor, membership, Permission và Data Scope trong sheet TEST_DATA. | M4: 201 | N4: 201; tạo user inactive, IAM account, preference, session state, challenge REGISTER; email OTP được gửi; không trả password/OTP | O4: pm.test('HTTP thuộc [201]', () => pm.expect([201]).to.include(pm.response.code)); pm.test('Response không lộ secret', () => { const t=pm.response.text().toLowerCase(); ['password','refresh_token','access_token','otp_code'].forEach(k => pm.expect(t).not.to.include(k)); }); | P4: Not Run | V4: =IF(P4="Not Run","Chưa chạy",IF(R4="","Thiếu Tester",IF(S4="","Thiếu Ngày chạy",IF(Q4="","Thiếu Actual Result",IF(AND(P4="Fail",T4=""),"Thiếu Defect ID",IF(AND(OR(P4="Fail",P4="Blocked"),U4=""),"Thiếu Evidence","Hợp lệ"))))))
A5: COM01-02 | B5: COM01-02 | C5: UC-COM-01 | D5: Xác thực bằng challenge và OTP đúng | E5: POST | F5: {{base_url}}/api/v1/common/auth/verify-registration/ | G5: Không cần token (public endpoint) | H5: Các biến {{...}} trong path phải lấy từ response/seed; xem cột chuẩn bị dữ liệu. | I5: Không có | J5: Accept: application/json Content-Type: application/json | K5: { "challenge": "{{registration_challenge}}", "code": "{{otp_code}}" } | L5: 1. Lấy challenge từ response trước đó và OTP từ email sandbox; không ghi OTP vào defect/evidence. 2. Điền UUID từ dữ liệu seed/staging; không tự đặt UUID giả nếu case yêu cầu object tồn tại. 3. Đối chiếu actor, membership, Permission và Data Scope trong sheet TEST_DATA. | M5: 200 | N5: 200; user ACTIVE, email được đánh dấu verified, OTP consumed, trả access/refresh và bước tiếp theo | O5: pm.test('HTTP thuộc [200]', () => pm.expect([200]).to.include(pm.response.code)); pm.test('Response không lộ secret', () => { const t=pm.response.text().toLowerCase(); ['password','refresh_token','access_token','otp_code'].forEach(k => pm.expect(t).not.to.include(k)); }); | P5: Not Run | V5: =IF(P5="Not Run","Chưa chạy",IF(R5="","Thiếu Tester",IF(S5="","Thiếu Ngày chạy",IF(Q5="","Thiếu Actual Result",IF(AND(P5="Fail",T5=""),"Thiếu Defect ID",IF(AND(OR(P5="Fail",P5="Blocked"),U5=""),"Thiếu Evidence","Hợp lệ"))))))
A6: COM01-03 | B6: COM01-03 | C6: UC-COM-01 | D6: Nhập sai OTP lần 1–4 | E6: POST | F6: {{base_url}}/api/v1/common/auth/verify-registration/ | G6: Không cần token (public endpoint) | H6: Các biến {{...}} trong path phải lấy từ response/seed; xem cột chuẩn bị dữ liệu. | I6: Không có | J6: Accept: application/json Content-Type: application/json | K6: { "challenge": "{{registration_challenge}}", "code": "{{otp_code}}" } | L6: 1. Lấy challenge từ response trước đó và OTP từ email sandbox; không ghi OTP vào defect/evidence. 2. Điền UUID từ dữ liệu seed/staging; không tự đặt UUID giả nếu case yêu cầu object tồn tại. 3. Đối chiếu actor, membership, Permission và Data Scope trong sheet TEST_DATA. | M6: 400 | N6: 400; không kích hoạt tài khoản; số lần thử tăng đúng | O6: pm.test('HTTP thuộc [400]', () => pm.expect([400]).to.include(pm.response.code)); pm.test('Response không lộ secret', () => { const t=pm.response.text().toLowerCase(); ['password','refresh_token','access_token','otp_code'].forEach(k => pm.expect(t).not.to.include(k)); }); | P6: Not Run | V6: =IF(P6="Not Run","Chưa chạy",IF(R6="","Thiếu Tester",IF(S6="","Thiếu Ngày chạy",IF(Q6="","Thiếu Actual Result",IF(AND(P6="Fail",T6=""),"Thiếu Defect ID",IF(AND(OR(P6="Fail",P6="Blocked"),U6=""),"Thiếu Evidence","Hợp lệ"))))))
A7: COM01-04 | B7: COM01-04 | C7: UC-COM-01 | D7: Nhập sai OTP lần 5 rồi nhập mã đúng | E7: POST | F7: {{base_url}}/api/v1/common/auth/verify-registration/ | G7: Không cần token (public endpoint) | H7: Các biến {{...}} trong path phải lấy từ response/seed; xem cột chuẩn bị dữ liệu. | I7: Không có | J7: Accept: application/json Content-Type: application/json | K7: { "challenge": "{{registration_challenge}}", "code": "{{otp_code}}" } | L7: 1. Lấy challenge từ response trước đó và OTP từ email sandbox; không ghi OTP vào defect/evidence. 2. Điền UUID từ dữ liệu seed/staging; không tự đặt UUID giả nếu case yêu cầu object tồn tại. 3. Đối chiếu actor, membership, Permission và Data Scope trong sheet TEST_DATA. | M7: 200 | N7: Challenge bị vô hiệu; mã đúng sau đó vẫn bị từ chối | O7: pm.test('HTTP thuộc [200]', () => pm.expect([200]).to.include(pm.response.code)); pm.test('Response không lộ secret', () => { const t=pm.response.text().toLowerCase(); ['password','refresh_token','access_token','otp_code'].forEach(k => pm.expect(t).not.to.include(k)); }); | P7: Not Run | V7: =IF(P7="Not Run","Chưa chạy",IF(R7="","Thiếu Tester",IF(S7="","Thiếu Ngày chạy",IF(Q7="","Thiếu Actual Result",IF(AND(P7="Fail",T7=""),"Thiếu Defect ID",IF(AND(OR(P7="Fail",P7="Blocked"),U7=""),"Thiếu Evidence","Hợp lệ"))))))
A8: COM01-05 | B8: COM01-05 | C8: UC-COM-01 | D8: OTP hết hạn hoặc đã dùng | E8: POST | F8: {{base_url}}/api/v1/common/auth/verify-registration/ | G8: Không cần token (public endpoint) | H8: Các biến {{...}} trong path phải lấy từ response/seed; xem cột chuẩn bị dữ liệu. | I8: Không có | J8: Accept: application/json Content-Type: application/json | K8: { "challenge": "{{registration_challenge}}", "code": "{{otp_code}}" } | L8: 1. Lấy challenge từ response trước đó và OTP từ email sandbox; không ghi OTP vào defect/evidence. 2. Điền UUID từ dữ liệu seed/staging; không tự đặt UUID giả nếu case yêu cầu object tồn tại. 3. Đối chiếu actor, membership, Permission và Data Scope trong sheet TEST_DATA. | M8: 400 | N8: 400; không kích hoạt; không thể replay OTP | O8: pm.test('HTTP thuộc [400]', () => pm.expect([400]).to.include(pm.response.code)); pm.test('Response không lộ secret', () => { const t=pm.response.text().toLowerCase(); ['password','refresh_token','access_token','otp_code'].forEach(k => pm.expect(t).not.to.include(k)); }); | P8: Not Run | V8: =IF(P8="Not Run","Chưa chạy",IF(R8="","Thiếu Tester",IF(S8="","Thiếu Ngày chạy",IF(Q8="","Thiếu Actual Result",IF(AND(P8="Fail",T8=""),"Thiếu Defect ID",IF(AND(OR(P8="Fail",P8="Blocked"),U8=""),"Thiếu Evidence","Hợp lệ"))))))
A9: COM01-06 | B9: COM01-06 | C9: UC-COM-01 | D9: Gửi lại OTP sau cooldown | E9: POST | F9: {{base_url}}/api/v1/common/auth/resend-verification/ | G9: Không cần token (public endpoint) | H9: Các biến {{...}} trong path phải lấy từ response/seed; xem cột chuẩn bị dữ liệu. | I9: Không có | J9: Accept: application/json Content-Type: application/json | K9: { "challenge": "{{registration_challenge}}" } | L9: 1. Lấy challenge từ response trước đó và OTP từ email sandbox; không ghi OTP vào defect/evidence. 2. Điền UUID từ dữ liệu seed/staging; không tự đặt UUID giả nếu case yêu cầu object tồn tại. 3. Đối chiếu actor, membership, Permission và Data Scope trong sheet TEST_DATA. | M9: 202 | N9: 202; challenge cũ consumed, challenge mới có hiệu lực, gửi đúng email | O9: pm.test('HTTP thuộc [202]', () => pm.expect([202]).to.include(pm.response.code)); pm.test('Response không lộ secret', () => { const t=pm.response.text().toLowerCase(); ['password','refresh_token','access_token','otp_code'].forEach(k => pm.expect(t).not.to.include(k)); }); | P9: Not Run | V9: =IF(P9="Not Run","Chưa chạy",IF(R9="","Thiếu Tester",IF(S9="","Thiếu Ngày chạy",IF(Q9="","Thiếu Actual Result",IF(AND(P9="Fail",T9=""),"Thiếu Defect ID",IF(AND(OR(P9="Fail",P9="Blocked"),U9=""),"Thiếu Evidence","Hợp lệ"))))))
A10: COM01-07 | B10: COM01-07 | C10: UC-COM-01 | D10: Gửi lại OTP trong 60 giây | E10: POST | F10: {{base_url}}/api/v1/common/auth/resend-verification/ | G10: Không cần token (public endpoint) | H10: Các biến {{...}} trong path phải lấy từ response/seed; xem cột chuẩn bị dữ liệu. | I10: Không có | J10: Accept: application/json Content-Type: application/json | K10: { "challenge": "{{registration_challenge}}" } | L10: 1. Lấy challenge từ response trước đó và OTP từ email sandbox; không ghi OTP vào defect/evidence. 2. Điền UUID từ dữ liệu seed/staging; không tự đặt UUID giả nếu case yêu cầu object tồn tại. 3. Đối chiếu actor, membership, Permission và Data Scope trong sheet TEST_DATA. | M10: 400 | N10: 400 và có retry_after; không gửi thêm email | O10: pm.test('HTTP thuộc [400]', () => pm.expect([400]).to.include(pm.response.code)); pm.test('Response không lộ secret', () => { const t=pm.response.text().toLowerCase(); ['password','refresh_token','access_token','otp_code'].forEach(k => pm.expect(t).not.to.include(k)); }); | P10: Not Run | V10: =IF(P10="Not Run","Chưa chạy",IF(R10="","Thiếu Tester",IF(S10="","Thiếu Ngày chạy",IF(Q10="","Thiếu Actual Result",IF(AND(P10="Fail",T10=""),"Thiếu Defect ID",IF(AND(OR(P10="Fail",P10="Blocked"),U10=""),"Thiếu Evidence","Hợp lệ"))))))
A11: COM01-08 | B11: COM01-08 | C11: UC-COM-01 | D11: Email/username/số điện thoại trùng, kể cả khác hoa thường | E11: POST | F11: {{base_url}}/api/v1/common/auth/register/ | G11: Không cần token (public endpoint) | H11: Các biến {{...}} trong path phải lấy từ response/seed; xem cột chuẩn bị dữ liệu. | I11: Không có | J11: Accept: application/json Content-Type: application/json | K11: { "username": "{{register_username}}", "email": "{{register_email}}", "phone": "{{register_phone}}", "display_name": "Người dùng QA", "password": "{{register_password}}", "password_confirm": "{{register_password_confirm}}", "terms_accepted": true, "terms_version": "2026-01", "privacy_version": "2026-01" } | L11: 1. Lấy challenge từ response trước đó và OTP từ email sandbox; không ghi OTP vào defect/evidence. 2. Điền UUID từ dữ liệu seed/staging; không tự đặt UUID giả nếu case yêu cầu object tồn tại. 3. Đối chiếu actor, membership, Permission và Data Scope trong sheet TEST_DATA. | M11: 400 | N11: 400; không tạo bản ghi dở dang | O11: pm.test('HTTP thuộc [400]', () => pm.expect([400]).to.include(pm.response.code)); pm.test('Response không lộ secret', () => { const t=pm.response.text().toLowerCase(); ['password','refresh_token','access_token','otp_code'].forEach(k => pm.expect(t).not.to.include(k)); }); | P11: Not Run | V11: =IF(P11="Not Run","Chưa chạy",IF(R11="","Thiếu Tester",IF(S11="","Thiếu Ngày chạy",IF(Q11="","Thiếu Actual Result",IF(AND(P11="Fail",T11=""),"Thiếu Defect ID",IF(AND(OR(P11="Fail",P11="Blocked"),U11=""),"Thiếu Evidence","Hợp lệ"))))))
A12: COM01-09 | B12: COM01-09 | C12: UC-COM-01 | D12: Mật khẩu yếu, xác nhận sai, chưa chấp nhận điều khoản | E12: POST | F12: {{base_url}}/api/v1/common/auth/register/ | G12: Không cần token (public endpoint) | H12: Các biến {{...}} trong path phải lấy từ response/seed; xem cột chuẩn bị dữ liệu. | I12: Không có | J12: Accept: application/json Content-Type: application/json | K12: { "username": "{{register_username}}", "email": "{{register_email}}", "phone": "{{register_phone}}", "display_name": "Người dùng QA", "password": "{{register_password}}", "password_confirm": "{{register_password_confirm}}", "terms_accepted": true, "terms_version": "2026-01", "privacy_version": "2026-01" } | L12: 1. Lấy challenge từ response trước đó và OTP từ email sandbox; không ghi OTP vào defect/evidence. 2. Điền UUID từ dữ liệu seed/staging; không tự đặt UUID giả nếu case yêu cầu object tồn tại. 3. Đối chiếu actor, membership, Permission và Data Scope trong sheet TEST_DATA. | M12: 400 | N12: 400 theo đúng field; không tạo user | O12: pm.test('HTTP thuộc [400]', () => pm.expect([400]).to.include(pm.response.code)); pm.test('Response không lộ secret', () => { const t=pm.response.text().toLowerCase(); ['password','refresh_token','access_token','otp_code'].forEach(k => pm.expect(t).not.to.include(k)); }); | P12: Not Run | V12: =IF(P12="Not Run","Chưa chạy",IF(R12="","Thiếu Tester",IF(S12="","Thiếu Ngày chạy",IF(Q12="","Thiếu Actual Result",IF(AND(P12="Fail",T12=""),"Thiếu Defect ID",IF(AND(OR(P12="Fail",P12="Blocked"),U12=""),"Thiếu Evidence","Hợp lệ"))))))
A13: COM01-10 | B13: COM01-10 | C13: UC-COM-01 | D13: Email/phone sai định dạng; tên chỉ có khoảng trắng; field vượt max length | E13: POST | F13: {{base_url}}/api/v1/common/auth/register/ | G13: Không cần token (public endpoint) | H13: Các biến {{...}} trong path phải lấy từ response/seed; xem cột chuẩn bị dữ liệu. | I13: Không có | J13: Accept: application/json Content-Type: application/json | K13: { "username": "{{register_username}}", "email": "{{register_email}}", "phone": "{{register_phone}}", "display_name": "Người dùng QA", "password": "{{register_password}}", "password_confirm": "{{register_password_confirm}}", "terms_accepted": true, "terms_version": "2026-01", "privacy_version": "2026-01" } | L13: 1. Lấy challenge từ response trước đó và OTP từ email sandbox; không ghi OTP vào defect/evidence. 2. Điền UUID từ dữ liệu seed/staging; không tự đặt UUID giả nếu case yêu cầu object tồn tại. 3. Đối chiếu actor, membership, Permission và Data Scope trong sheet TEST_DATA. | M13: 400 | N13: 400 và thông báo validation phù hợp | O13: pm.test('HTTP thuộc [400]', () => pm.expect([400]).to.include(pm.response.code)); pm.test('Response không lộ secret', () => { const t=pm.response.text().toLowerCase(); ['password','refresh_token','access_token','otp_code'].forEach(k => pm.expect(t).not.to.include(k)); }); | P13: Not Run | V13: =IF(P13="Not Run","Chưa chạy",IF(R13="","Thiếu Tester",IF(S13="","Thiếu Ngày chạy",IF(Q13="","Thiếu Actual Result",IF(AND(P13="Fail",T13=""),"Thiếu Defect ID",IF(AND(OR(P13="Fail",P13="Blocked"),U13=""),"Thiếu Evidence","Hợp lệ"))))))
A14: COM01-11 | B14: COM01-11 | C14: UC-COM-01 | D14: Đổi email khi đang chờ xác thực bằng challenge hợp lệ | E14: POST | F14: {{base_url}}/api/v1/common/auth/change-registration-email/ | G14: Không cần token (public endpoint) | H14: Các biến {{...}} trong path phải lấy từ response/seed; xem cột chuẩn bị dữ liệu. | I14: Không có | J14: Accept: application/json Content-Type: application/json | K14: { "challenge": "{{registration_challenge}}", "email": "{{changed_email}}" } | L14: 1. Lấy challenge từ response trước đó và OTP từ email sandbox; không ghi OTP vào defect/evidence. 2. Điền UUID từ dữ liệu seed/staging; không tự đặt UUID giả nếu case yêu cầu object tồn tại. 3. Đối chiếu actor, membership, Permission và Data Scope trong sheet TEST_DATA. | M14: 200 | N14: Email/user preference cập nhật; OTP cũ mất hiệu lực; OTP mới gửi đến email mới | O14: pm.test('HTTP thuộc [200]', () => pm.expect([200]).to.include(pm.response.code)); pm.test('Response không lộ secret', () => { const t=pm.response.text().toLowerCase(); ['password','refresh_token','access_token','otp_code'].forEach(k => pm.expect(t).not.to.include(k)); }); | P14: Not Run | V14: =IF(P14="Not Run","Chưa chạy",IF(R14="","Thiếu Tester",IF(S14="","Thiếu Ngày chạy",IF(Q14="","Thiếu Actual Result",IF(AND(P14="Fail",T14=""),"Thiếu Defect ID",IF(AND(OR(P14="Fail",P14="Blocked"),U14=""),"Thiếu Evidence","Hợp lệ"))))))
A15: COM01-12 | B15: COM01-12 | C15: UC-COM-01 | D15: Đổi sang email đã dùng hoặc dùng challenge của đăng ký đã active | E15: POST | F15: {{base_url}}/api/v1/common/auth/change-registration-email/ | G15: Không cần token (public endpoint) | H15: Các biến {{...}} trong path phải lấy từ response/seed; xem cột chuẩn bị dữ liệu. | I15: Không có | J15: Accept: application/json Content-Type: application/json | K15: { "challenge": "{{registration_challenge}}", "email": "{{changed_email}}" } | L15: 1. Lấy challenge từ response trước đó và OTP từ email sandbox; không ghi OTP vào defect/evidence. 2. Điền UUID từ dữ liệu seed/staging; không tự đặt UUID giả nếu case yêu cầu object tồn tại. 3. Đối chiếu actor, membership, Permission và Data Scope trong sheet TEST_DATA. | M15: 400 | N15: 400; không thay đổi email | O15: pm.test('HTTP thuộc [400]', () => pm.expect([400]).to.include(pm.response.code)); pm.test('Response không lộ secret', () => { const t=pm.response.text().toLowerCase(); ['password','refresh_token','access_token','otp_code'].forEach(k => pm.expect(t).not.to.include(k)); }); | P15: Not Run | V15: =IF(P15="Not Run","Chưa chạy",IF(R15="","Thiếu Tester",IF(S15="","Thiếu Ngày chạy",IF(Q15="","Thiếu Actual Result",IF(AND(P15="Fail",T15=""),"Thiếu Defect ID",IF(AND(OR(P15="Fail",P15="Blocked"),U15=""),"Thiếu Evidence","Hợp lệ"))))))
... A149: COM12-16 | B149: COM12-16 | C149: UC-COM-12 | D149: Nội dung output có HTML/script/công thức nguy hiểm | E149: POST | F149: {{base_url}}/api/v1/common/ai/query/ | G149: {{access_token}} – actor theo TEST_DATA | H149: Các biến {{...}} trong path phải lấy từ response/seed; xem cột chuẩn bị dữ liệu. | I149: Không có | J149: Authorization: Bearer {{access_token}} Accept: application/json Content-Type: application/json | K149: { "company": "{{c1_id}}", "conversation": "{{ai_conversation_id}}", "question": "{{ai_question}}", "request_type": "ANALYSIS", "request_id": "{{$guid}}", "context": {"screen": "dashboard"} } | L149: 1. Chạy request đăng nhập phù hợp và lưu access token vào Environment. 2. Điền UUID từ dữ liệu seed/staging; không tự đặt UUID giả nếu case yêu cầu object tồn tại. 3. Đối chiếu actor, membership, Permission và Data Scope trong sheet TEST_DATA. | M149: 201 | N149: UI encode/sanitize; không XSS; disclaimer luôn hiển thị | O149: pm.test('HTTP thuộc [201]', () => pm.expect([201]).to.include(pm.response.code)); pm.test('Response không lộ secret', () => { const t=pm.response.text().toLowerCase(); ['password','refresh_token','access_token','otp_code'].forEach(k => pm.expect(t).not.to.include(k)); }); | P149: Not Run | V149: =IF(P149="Not Run","Chưa chạy",IF(R149="","Thiếu Tester",IF(S149="","Thiếu Ngày chạy",IF(Q149="","Thiếu Actual Result",IF(AND(P149="Fail",T149=""),"Thiếu Defect ID",IF(AND(OR(P149="Fail",P149="Blocked"),U149=""),"Thiếu Evidence","Hợp lệ"))))))

Sheet COM-01
A1: UC-COM-01 – Đăng ký và xác thực tài khoản
A2: Nguồn: COMMON_SERVICES_TEST_PLAN.md | 14 test case
A3: STT | B3: Test Case ID | C3: UC ID | D3: Tên test case | E3: Priority | F3: Loại kiểm thử | G3: Lớp | H3: Endpoint/API | I3: Điều kiện trước | J3: Dữ liệu kiểm thử | K3: Các bước thực hiện | L3: Kết quả mong đợi | M3: Hậu điều kiện cần kiểm tra | N3: Actual Result | O3: Status | P3: Severity nếu lỗi | Q3: Defect ID | R3: Tester | S3: Ngày chạy | T3: Evidence/Link | U3: Automation | V3: Ghi chú
A4: 1 | B4: COM01-01 | C4: UC-COM-01 | D4: Đăng ký đủ dữ liệu hợp lệ và chấp nhận điều khoản | E4: P0 | F4: Functional | G4: API + UI/E2E | H4: POST /api/v1/common/auth/register/ POST /api/v1/common/auth/verify-registration/ POST /api/v1/common/auth/resend-verification/ POST /api/v1/common/auth/change-registration-email/ | I4: Email/username/phone chưa tồn tại, trừ khi test case yêu cầu dữ liệu trùng. Email sandbox hoạt động. | J4: email=qa.com01+<timestamp>@example.com; username=qa_com01_<timestamp>; phone=0901<6 số>; password=StrongPass!2026 | K4: 1. Chuẩn bị dữ liệu đúng mục 'Điều kiện trước' và ghi lại các ID ban đầu. 2. Mở màn hình/API tương ứng ở trạng thái chưa xác thực, trừ khi kịch bản yêu cầu session có sẵn. 3. Thực hiện kịch bản: Đăng ký đủ dữ liệu hợp lệ và chấp nhận điều khoản. 4. Ghi lại HTTP status, response body và thông báo/điều hướng trên UI (nếu có). 5. Kiểm tra response, email sandbox, trạng thái user/challenge và không để lộ password/OTP. 6. So sánh toàn bộ kết quả với cột 'Kết quả mong đợi' và đính kèm evidence nếu Fail/Blocked. | L4: 201; tạo user inactive, IAM account, preference, session state, challenge REGISTER; email OTP được gửi; không trả password/OTP | M4: User, IAM account, preference và challenge nhất quán; không có user rác khi validation lỗi. | O4: Not Run | U4: Candidate
A5: 2 | B5: COM01-02 | C5: UC-COM-01 | D5: Xác thực bằng challenge và OTP đúng | E5: P0 | F5: Functional | G5: API + UI/E2E | H5: POST /api/v1/common/auth/register/ POST /api/v1/common/auth/verify-registration/ POST /api/v1/common/auth/resend-verification/ POST /api/v1/common/auth/change-registration-email/ | I5: Email/username/phone chưa tồn tại, trừ khi test case yêu cầu dữ liệu trùng. Email sandbox hoạt động. | J5: email=qa.com01+<timestamp>@example.com; username=qa_com01_<timestamp>; phone=0901<6 số>; password=StrongPass!2026 Bổ sung: OTP đúng: lấy từ email sandbox; OTP sai: 000000; challenge UUID từ response | K5: 1. Chuẩn bị dữ liệu đúng mục 'Điều kiện trước' và ghi lại các ID ban đầu. 2. Mở màn hình/API tương ứng ở trạng thái chưa xác thực, trừ khi kịch bản yêu cầu session có sẵn. 3. Thực hiện kịch bản: Xác thực bằng challenge và OTP đúng. 4. Ghi lại HTTP status, response body và thông báo/điều hướng trên UI (nếu có). 5. Kiểm tra response, email sandbox, trạng thái user/challenge và không để lộ password/OTP. 6. So sánh toàn bộ kết quả với cột 'Kết quả mong đợi' và đính kèm evidence nếu Fail/Blocked. | L5: 200; user ACTIVE, email được đánh dấu verified, OTP consumed, trả access/refresh và bước tiếp theo | M5: User, IAM account, preference và challenge nhất quán; không có user rác khi validation lỗi. | O5: Not Run | U5: Candidate
A6: 3 | B6: COM01-03 | C6: UC-COM-01 | D6: Nhập sai OTP lần 1–4 | E6: P0 | F6: Functional | G6: API + UI/E2E | H6: POST /api/v1/common/auth/register/ POST /api/v1/common/auth/verify-registration/ POST /api/v1/common/auth/resend-verification/ POST /api/v1/common/auth/change-registration-email/ | I6: Email/username/phone chưa tồn tại, trừ khi test case yêu cầu dữ liệu trùng. Email sandbox hoạt động. | J6: email=qa.com01+<timestamp>@example.com; username=qa_com01_<timestamp>; phone=0901<6 số>; password=StrongPass!2026 Bổ sung: OTP đúng: lấy từ email sandbox; OTP sai: 000000; challenge UUID từ response; AI stub hỗ trợ success, timeout, HTTP 500, invalid JSON và oversized response | K6: 1. Chuẩn bị dữ liệu đúng mục 'Điều kiện trước' và ghi lại các ID ban đầu. 2. Mở màn hình/API tương ứng ở trạng thái chưa xác thực, trừ khi kịch bản yêu cầu session có sẵn. 3. Thực hiện kịch bản: Nhập sai OTP lần 1–4. 4. Ghi lại HTTP status, response body và thông báo/điều hướng trên UI (nếu có). 5. Kiểm tra response, email sandbox, trạng thái user/challenge và không để lộ password/OTP. 6. So sánh toàn bộ kết quả với cột 'Kết quả mong đợi' và đính kèm evidence nếu Fail/Blocked. | L6: 400; không kích hoạt tài khoản; số lần thử tăng đúng | M6: User, IAM account, preference và challenge nhất quán; không có user rác khi validation lỗi. | O6: Not Run | U6: Candidate
A7: 4 | B7: COM01-04 | C7: UC-COM-01 | D7: Nhập sai OTP lần 5 rồi nhập mã đúng | E7: P0 | F7: Functional | G7: API + UI/E2E | H7: POST /api/v1/common/auth/register/ POST /api/v1/common/auth/verify-registration/ POST /api/v1/common/auth/resend-verification/ POST /api/v1/common/auth/change-registration-email/ | I7: Email/username/phone chưa tồn tại, trừ khi test case yêu cầu dữ liệu trùng. Email sandbox hoạt động. | J7: email=qa.com01+<timestamp>@example.com; username=qa_com01_<timestamp>; phone=0901<6 số>; password=StrongPass!2026 Bổ sung: OTP đúng: lấy từ email sandbox; OTP sai: 000000; challenge UUID từ response; AI stub hỗ trợ success, timeout, HTTP 500, invalid JSON và oversized response | K7: 1. Chuẩn bị dữ liệu đúng mục 'Điều kiện trước' và ghi lại các ID ban đầu. 2. Mở màn hình/API tương ứng ở trạng thái chưa xác thực, trừ khi kịch bản yêu cầu session có sẵn. 3. Thực hiện kịch bản: Nhập sai OTP lần 5 rồi nhập mã đúng. 4. Ghi lại HTTP status, response body và thông báo/điều hướng trên UI (nếu có). 5. Kiểm tra response, email sandbox, trạng thái user/challenge và không để lộ password/OTP. 6. So sánh toàn bộ kết quả với cột 'Kết quả mong đợi' và đính kèm evidence nếu Fail/Blocked. | L7: Challenge bị vô hiệu; mã đúng sau đó vẫn bị từ chối | M7: User, IAM account, preference và challenge nhất quán; không có user rác khi validation lỗi. | O7: Not Run | U7: Candidate
A8: 5 | B8: COM01-05 | C8: UC-COM-01 | D8: OTP hết hạn hoặc đã dùng | E8: P0 | F8: Functional | G8: API + UI/E2E | H8: POST /api/v1/common/auth/register/ POST /api/v1/common/auth/verify-registration/ POST /api/v1/common/auth/resend-verification/ POST /api/v1/common/auth/change-registration-email/ | I8: Email/username/phone chưa tồn tại, trừ khi test case yêu cầu dữ liệu trùng. Email sandbox hoạt động. | J8: email=qa.com01+<timestamp>@example.com; username=qa_com01_<timestamp>; phone=0901<6 số>; password=StrongPass!2026 Bổ sung: OTP đúng: lấy từ email sandbox; OTP sai: 000000; challenge UUID từ response; Điều chỉnh expires_at về quá khứ bằng fixture/admin test | K8: 1. Chuẩn bị dữ liệu đúng mục 'Điều kiện trước' và ghi lại các ID ban đầu. 2. Mở màn hình/API tương ứng ở trạng thái chưa xác thực, trừ khi kịch bản yêu cầu session có sẵn. 3. Thực hiện kịch bản: OTP hết hạn hoặc đã dùng. 4. Ghi lại HTTP status, response body và thông báo/điều hướng trên UI (nếu có). 5. Kiểm tra response, email sandbox, trạng thái user/challenge và không để lộ password/OTP. 6. So sánh toàn bộ kết quả với cột 'Kết quả mong đợi' và đính kèm evidence nếu Fail/Blocked. | L8: 400; không kích hoạt; không thể replay OTP | M8: User, IAM account, preference và challenge nhất quán; không có user rác khi validation lỗi. | O8: Not Run | U8: Candidate
A9: 6 | B9: COM01-06 | C9: UC-COM-01 | D9: Gửi lại OTP sau cooldown | E9: P1 | F9: Functional | G9: API + UI/E2E | H9: POST /api/v1/common/auth/register/ POST /api/v1/common/auth/verify-registration/ POST /api/v1/common/auth/resend-verification/ POST /api/v1/common/auth/change-registration-email/ | I9: Email/username/phone chưa tồn tại, trừ khi test case yêu cầu dữ liệu trùng. Email sandbox hoạt động. | J9: email=qa.com01+<timestamp>@example.com; username=qa_com01_<timestamp>; phone=0901<6 số>; password=StrongPass!2026 Bổ sung: OTP đúng: lấy từ email sandbox; OTP sai: 000000; challenge UUID từ response | K9: 1. Chuẩn bị dữ liệu đúng mục 'Điều kiện trước' và ghi lại các ID ban đầu. 2. Mở màn hình/API tương ứng ở trạng thái chưa xác thực, trừ khi kịch bản yêu cầu session có sẵn. 3. Thực hiện kịch bản: Gửi lại OTP sau cooldown. 4. Ghi lại HTTP status, response body và thông báo/điều hướng trên UI (nếu có). 5. Kiểm tra response, email sandbox, trạng thái user/challenge và không để lộ password/OTP. 6. So sánh toàn bộ kết quả với cột 'Kết quả mong đợi' và đính kèm evidence nếu Fail/Blocked. | L9: 202; challenge cũ consumed, challenge mới có hiệu lực, gửi đúng email | M9: User, IAM account, preference và challenge nhất quán; không có user rác khi validation lỗi. | O9: Not Run | U9: Candidate
A10: 7 | B10: COM01-07 | C10: UC-COM-01 | D10: Gửi lại OTP trong 60 giây | E10: P1 | F10: Functional | G10: API + UI/E2E | H10: POST /api/v1/common/auth/register/ POST /api/v1/common/auth/verify-registration/ POST /api/v1/common/auth/resend-verification/ POST /api/v1/common/auth/change-registration-email/ | I10: Email/username/phone chưa tồn tại, trừ khi test case yêu cầu dữ liệu trùng. Email sandbox hoạt động. | J10: email=qa.com01+<timestamp>@example.com; username=qa_com01_<timestamp>; phone=0901<6 số>; password=StrongPass!2026 Bổ sung: OTP đúng: lấy từ email sandbox; OTP sai: 000000; challenge UUID từ response | K10: 1. Chuẩn bị dữ liệu đúng mục 'Điều kiện trước' và ghi lại các ID ban đầu. 2. Mở màn hình/API tương ứng ở trạng thái chưa xác thực, trừ khi kịch bản yêu cầu session có sẵn. 3. Thực hiện kịch bản: Gửi lại OTP trong 60 giây. 4. Ghi lại HTTP status, response body và thông báo/điều hướng trên UI (nếu có). 5. Kiểm tra response, email sandbox, trạng thái user/challenge và không để lộ password/OTP. 6. So sánh toàn bộ kết quả với cột 'Kết quả mong đợi' và đính kèm evidence nếu Fail/Blocked. | L10: 400 và có retry_after; không gửi thêm email | M10: User, IAM account, preference và challenge nhất quán; không có user rác khi validation lỗi. | O10: Not Run | U10: Candidate
A11: 8 | B11: COM01-08 | C11: UC-COM-01 | D11: Email/username/số điện thoại trùng, kể cả khác hoa thường | E11: P0 | F11: Functional | G11: API + UI/E2E | H11: POST /api/v1/common/auth/register/ POST /api/v1/common/auth/verify-registration/ POST /api/v1/common/auth/resend-verification/ POST /api/v1/common/auth/change-registration-email/ | I11: Email/username/phone chưa tồn tại, trừ khi test case yêu cầu dữ liệu trùng. Email sandbox hoạt động. | J11: email=qa.com01+<timestamp>@example.com; username=qa_com01_<timestamp>; phone=0901<6 số>; password=StrongPass!2026 Bổ sung: Chuẩn bị trước một bản ghi có cùng giá trị cần kiểm tra; AI stub hỗ trợ success, timeout, HTTP 500, invalid JSON và oversized response | K11: 1. Chuẩn bị dữ liệu đúng mục 'Điều kiện trước' và ghi lại các ID ban đầu. 2. Mở màn hình/API tương ứng ở trạng thái chưa xác thực, trừ khi kịch bản yêu cầu session có sẵn. 3. Thực hiện kịch bản: Email/username/số điện thoại trùng, kể cả khác hoa thường. 4. Ghi lại HTTP status, response body và thông báo/điều hướng trên UI (nếu có). 5. Kiểm tra response, email sandbox, trạng thái user/challenge và không để lộ password/OTP. 6. So sánh toàn bộ kết quả với cột 'Kết quả mong đợi' và đính kèm evidence nếu Fail/Blocked. | L11: 400; không tạo bản ghi dở dang | M11: User, IAM account, preference và challenge nhất quán; không có user rác khi validation lỗi. | O11: Not Run | U11: Candidate
A12: 9 | B12: COM01-09 | C12: UC-COM-01 | D12: Mật khẩu yếu, xác nhận sai, chưa chấp nhận điều khoản | E12: P1 | F12: Functional | G12: API + UI/E2E | H12: POST /api/v1/common/auth/register/ POST /api/v1/common/auth/verify-registration/ POST /api/v1/common/auth/resend-verification/ POST /api/v1/common/auth/change-registration-email/ | I12: Email/username/phone chưa tồn tại, trừ khi test case yêu cầu dữ liệu trùng. Email sandbox hoạt động. | J12: email=qa.com01+<timestamp>@example.com; username=qa_com01_<timestamp>; phone=0901<6 số>; password=StrongPass!2026 Bổ sung: password yếu: 12345678 / password / khongKyTuDacBiet1; AI stub hỗ trợ success, timeout, HTTP 500, invalid JSON và oversized response | K12: 1. Chuẩn bị dữ liệu đúng mục 'Điều kiện trước' và ghi lại các ID ban đầu. 2. Mở màn hình/API tương ứng ở trạng thái chưa xác thực, trừ khi kịch bản yêu cầu session có sẵn. 3. Thực hiện kịch bản: Mật khẩu yếu, xác nhận sai, chưa chấp nhận điều khoản. 4. Ghi lại HTTP status, response body và thông báo/điều hướng trên UI (nếu có). 5. Kiểm tra response, email sandbox, trạng thái user/challenge và không để lộ password/OTP. 6. So sánh toàn bộ kết quả với cột 'Kết quả mong đợi' và đính kèm evidence nếu Fail/Blocked. | L12: 400 theo đúng field; không tạo user | M12: User, IAM account, preference và challenge nhất quán; không có user rác khi validation lỗi. | O12: Not Run | U12: Candidate
A13: 10 | B13: COM01-10 | C13: UC-COM-01 | D13: Email/phone sai định dạng; tên chỉ có khoảng trắng; field vượt max length | E13: P1 | F13: Functional | G13: API + UI/E2E | H13: POST /api/v1/common/auth/register/ POST /api/v1/common/auth/verify-registration/ POST /api/v1/common/auth/resend-verification/ POST /api/v1/common/auth/change-registration-email/ | I13: Email/username/phone chưa tồn tại, trừ khi test case yêu cầu dữ liệu trùng. Email sandbox hoạt động. | J13: email=qa.com01+<timestamp>@example.com; username=qa_com01_<timestamp>; phone=0901<6 số>; password=StrongPass!2026 Bổ sung: AI stub hỗ trợ success, timeout, HTTP 500, invalid JSON và oversized response | K13: 1. Chuẩn bị dữ liệu đúng mục 'Điều kiện trước' và ghi lại các ID ban đầu. 2. Mở màn hình/API tương ứng ở trạng thái chưa xác thực, trừ khi kịch bản yêu cầu session có sẵn. 3. Thực hiện kịch bản: Email/phone sai định dạng; tên chỉ có khoảng trắng; field vượt max length. 4. Ghi lại HTTP status, response body và thông báo/điều hướng trên UI (nếu có). 5. Kiểm tra response, email sandbox, trạng thái user/challenge và không để lộ password/OTP. 6. So sánh toàn bộ kết quả với cột 'Kết quả mong đợi' và đính kèm evidence nếu Fail/Blocked. | L13: 400 và thông báo validation phù hợp | M13: User, IAM account, preference và challenge nhất quán; không có user rác khi validation lỗi. | O13: Not Run | U13: Candidate
A14: 11 | B14: COM01-11 | C14: UC-COM-01 | D14: Đổi email khi đang chờ xác thực bằng challenge hợp lệ | E14: P1 | F14: Functional | G14: API + UI/E2E | H14: POST /api/v1/common/auth/register/ POST /api/v1/common/auth/verify-registration/ POST /api/v1/common/auth/resend-verification/ POST /api/v1/common/auth/change-registration-email/ | I14: Email/username/phone chưa tồn tại, trừ khi test case yêu cầu dữ liệu trùng. Email sandbox hoạt động. | J14: email=qa.com01+<timestamp>@example.com; username=qa_com01_<timestamp>; phone=0901<6 số>; password=StrongPass!2026 Bổ sung: AI stub hỗ trợ success, timeout, HTTP 500, invalid JSON và oversized response | K14: 1. Chuẩn bị dữ liệu đúng mục 'Điều kiện trước' và ghi lại các ID ban đầu. 2. Mở màn hình/API tương ứng ở trạng thái chưa xác thực, trừ khi kịch bản yêu cầu session có sẵn. 3. Thực hiện kịch bản: Đổi email khi đang chờ xác thực bằng challenge hợp lệ. 4. Ghi lại HTTP status, response body và thông báo/điều hướng trên UI (nếu có). 5. Kiểm tra response, email sandbox, trạng thái user/challenge và không để lộ password/OTP. 6. So sánh toàn bộ kết quả với cột 'Kết quả mong đợi' và đính kèm evidence nếu Fail/Blocked. | L14: Email/user preference cập nhật; OTP cũ mất hiệu lực; OTP mới gửi đến email mới | M14: User, IAM account, preference và challenge nhất quán; không có user rác khi validation lỗi. | O14: Not Run | U14: Candidate
A15: 12 | B15: COM01-12 | C15: UC-COM-01 | D15: Đổi sang email đã dùng hoặc dùng challenge của đăng ký đã active | E15: P0 | F15: Functional | G15: API + UI/E2E | H15: POST /api/v1/common/auth/register/ POST /api/v1/common/auth/verify-registration/ POST /api/v1/common/auth/resend-verification/ POST /api/v1/common/auth/change-registration-email/ | I15: Email/username/phone chưa tồn tại, trừ khi test case yêu cầu dữ liệu trùng. Email sandbox hoạt động. | J15: email=qa.com01+<timestamp>@example.com; username=qa_com01_<timestamp>; phone=0901<6 số>; password=StrongPass!2026 Bổ sung: AI stub hỗ trợ success, timeout, HTTP 500, invalid JSON và oversized response | K15: 1. Chuẩn bị dữ liệu đúng mục 'Điều kiện trước' và ghi lại các ID ban đầu. 2. Mở màn hình/API tương ứng ở trạng thái chưa xác thực, trừ khi kịch bản yêu cầu session có sẵn. 3. Thực hiện kịch bản: Đổi sang email đã dùng hoặc dùng challenge của đăng ký đã active. 4. Ghi lại HTTP status, response body và thông báo/điều hướng trên UI (nếu có). 5. Kiểm tra response, email sandbox, trạng thái user/challenge và không để lộ password/OTP. 6. So sánh toàn bộ kết quả với cột 'Kết quả mong đợi' và đính kèm evidence nếu Fail/Blocked. | L15: 400; không thay đổi email | M15: User, IAM account, preference và challenge nhất quán; không có user rác khi validation lỗi. | O15: Not Run | U15: Candidate
... A17: 14 | B17: COM01-14 | C17: UC-COM-01 | D17: Vượt rate limit đăng ký/OTP theo email hoặc IP | E17: P0 | F17: Security/Authorization | G17: API + Integration | H17: POST /api/v1/common/auth/register/ POST /api/v1/common/auth/verify-registration/ POST /api/v1/common/auth/resend-verification/ POST /api/v1/common/auth/change-registration-email/ | I17: Email/username/phone chưa tồn tại, trừ khi test case yêu cầu dữ liệu trùng. Email sandbox hoạt động. | J17: email=qa.com01+<timestamp>@example.com; username=qa_com01_<timestamp>; phone=0901<6 số>; password=StrongPass!2026 Bổ sung: OTP đúng: lấy từ email sandbox; OTP sai: 000000; challenge UUID từ response; Gửi request liên tiếp vượt ngưỡng cấu hình từ cùng identifier/IP; AI stub hỗ trợ success, timeout, HTTP 500, invalid JSON và oversized response | K17: 1. Chuẩn bị dữ liệu đúng mục 'Điều kiện trước' và ghi lại các ID ban đầu. 2. Mở màn hình/API tương ứng ở trạng thái chưa xác thực, trừ khi kịch bản yêu cầu session có sẵn. 3. Thực hiện kịch bản: Vượt rate limit đăng ký/OTP theo email hoặc IP. 4. Ghi lại HTTP status, response body và thông báo/điều hướng trên UI (nếu có). 5. Kiểm tra response, email sandbox, trạng thái user/challenge và không để lộ password/OTP. 6. So sánh toàn bộ kết quả với cột 'Kết quả mong đợi' và đính kèm evidence nếu Fail/Blocked. | L17: 429; khóa theo bucket đúng và không làm lộ OTP/dữ liệu tài khoản | M17: User, IAM account, preference và challenge nhất quán; không có user rác khi validation lỗi. | O17: Not Run | U17: Candidate

Sheet COM-02
A1: UC-COM-02 – Gửi yêu cầu tham gia doanh nghiệp
A2: Nguồn: COMMON_SERVICES_TEST_PLAN.md | 14 test case
A3: STT | B3: Test Case ID | C3: UC ID | D3: Tên test case | E3: Priority | F3: Loại kiểm thử | G3: Lớp | H3: Endpoint/API | I3: Điều kiện trước | J3: Dữ liệu kiểm thử | K3: Các bước thực hiện | L3: Kết quả mong đợi | M3: Hậu điều kiện cần kiểm tra | N3: Actual Result | O3: Status | P3: Severity nếu lỗi | Q3: Defect ID | R3: Tester | S3: Ngày chạy | T3: Evidence/Link | U3: Automation | V3: Ghi chú
A4: 1 | B4: COM02-01 | C4: UC-COM-02 | D4: Tìm doanh nghiệp theo mã/tên/mã số thuế với từ khóa >= 2 ký tự | E4: P1 | F4: Security/Authorization | G4: API + Integration | H4: GET /api/v1/common/companies/search/ GET|POST /api/v1/common/join-requests/ POST /api/v1/common/join-requests/{id}/cancel/ GET /api/v1/common/company-join-requests/ POST /api/v1/common/company-join-requests/{id}/decide/ | I4: Có U2 (applicant), U7 (admin C1), C1 ACTIVE và Permission phù hợp theo từng test case. | J4: applicant=U2; admin=U7; company=C1; message=Xin tham gia doanh nghiệp | K4: 1. Chuẩn bị dữ liệu đúng mục 'Điều kiện trước' và ghi lại các ID ban đầu. 2. Đăng nhập bằng đúng actor/role và chọn company/branch theo điều kiện trước. 3. Thực hiện kịch bản: Tìm doanh nghiệp theo mã/tên/mã số thuế với từ khóa >= 2 ký tự. 4. Ghi lại HTTP status, response body và thông báo/điều hướng trên UI (nếu có). 5. Kiểm tra request, membership, quyết định, thông báo và quyền của cả applicant/admin. 6. So sánh toàn bộ kết quả với cột 'Kết quả mong đợi' và đính kèm evidence nếu Fail/Blocked. | L4: Chỉ trả doanh nghiệp ACTIVE, tối đa 20; mã số thuế được che chỉ còn 4 số cuối | M4: Không có pending request/membership/notification trùng; decided_by/at chính xác. | O4: Not Run | U4: Candidate
A5: 2 | B5: COM02-02 | C5: UC-COM-02 | D5: Từ khóa tìm doanh nghiệp < 2 ký tự | E5: P1 | F5: Security/Authorization | G5: API + Integration | H5: GET /api/v1/common/companies/search/ GET|POST /api/v1/common/join-requests/ POST /api/v1/common/join-requests/{id}/cancel/ GET /api/v1/common/company-join-requests/ POST /api/v1/common/company-join-requests/{id}/decide/ | I5: Có U2 (applicant), U7 (admin C1), C1 ACTIVE và Permission phù hợp theo từng test case. | J5: applicant=U2; admin=U7; company=C1; message=Xin tham gia doanh nghiệp | K5: 1. Chuẩn bị dữ liệu đúng mục 'Điều kiện trước' và ghi lại các ID ban đầu. 2. Đăng nhập bằng đúng actor/role và chọn company/branch theo điều kiện trước. 3. Thực hiện kịch bản: Từ khóa tìm doanh nghiệp < 2 ký tự. 4. Ghi lại HTTP status, response body và thông báo/điều hướng trên UI (nếu có). 5. Kiểm tra request, membership, quyết định, thông báo và quyền của cả applicant/admin. 6. So sánh toàn bộ kết quả với cột 'Kết quả mong đợi' và đính kèm evidence nếu Fail/Blocked. | L5: 400; không trả toàn bộ danh sách | M5: Không có pending request/membership/notification trùng; decided_by/at chính xác. | O5: Not Run | U5: Candidate
A6: 3 | B6: COM02-03 | C6: UC-COM-02 | D6: Gửi yêu cầu hợp lệ tới C1 | E6: P0 | F6: Functional | G6: API + UI/E2E | H6: GET /api/v1/common/companies/search/ GET|POST /api/v1/common/join-requests/ POST /api/v1/common/join-requests/{id}/cancel/ GET /api/v1/common/company-join-requests/ POST /api/v1/common/company-join-requests/{id}/decide/ | I6: Có U2 (applicant), U7 (admin C1), C1 ACTIVE và Permission phù hợp theo từng test case. | J6: applicant=U2; admin=U7; company=C1; message=Xin tham gia doanh nghiệp | K6: 1. Chuẩn bị dữ liệu đúng mục 'Điều kiện trước' và ghi lại các ID ban đầu. 2. Đăng nhập bằng đúng actor/role và chọn company/branch theo điều kiện trước. 3. Thực hiện kịch bản: Gửi yêu cầu hợp lệ tới C1. 4. Ghi lại HTTP status, response body và thông báo/điều hướng trên UI (nếu có). 5. Kiểm tra request, membership, quyết định, thông báo và quyền của cả applicant/admin. 6. So sánh toàn bộ kết quả với cột 'Kết quả mong đợi' và đính kèm evidence nếu Fail/Blocked. | L6: 201; status PENDING, requester là user hiện tại, ngày hết hạn đúng; thông báo cho requester/admin | M6: Không có pending request/membership/notification trùng; decided_by/at chính xác. | O6: Not Run | U6: Candidate
A7: 4 | B7: COM02-04 | C7: UC-COM-02 | D7: Gửi yêu cầu PENDING trùng C1 | E7: P0 | F7: Functional | G7: API + UI/E2E | H7: GET /api/v1/common/companies/search/ GET|POST /api/v1/common/join-requests/ POST /api/v1/common/join-requests/{id}/cancel/ GET /api/v1/common/company-join-requests/ POST /api/v1/common/company-join-requests/{id}/decide/ | I7: Có U2 (applicant), U7 (admin C1), C1 ACTIVE và Permission phù hợp theo từng test case. | J7: applicant=U2; admin=U7; company=C1; message=Xin tham gia doanh nghiệp Bổ sung: Chuẩn bị trước một bản ghi có cùng giá trị cần kiểm tra | K7: 1. Chuẩn bị dữ liệu đúng mục 'Điều kiện trước' và ghi lại các ID ban đầu. 2. Đăng nhập bằng đúng actor/role và chọn company/branch theo điều kiện trước. 3. Thực hiện kịch bản: Gửi yêu cầu PENDING trùng C1. 4. Ghi lại HTTP status, response body và thông báo/điều hướng trên UI (nếu có). 5. Kiểm tra request, membership, quyết định, thông báo và quyền của cả applicant/admin. 6. So sánh toàn bộ kết quả với cột 'Kết quả mong đợi' và đính kèm evidence nếu Fail/Blocked. | L7: 400; chỉ tồn tại một yêu cầu pending | M7: Không có pending request/membership/notification trùng; decided_by/at chính xác. | O7: Not Run | U7: Candidate
A8: 5 | B8: COM02-05 | C8: UC-COM-02 | D8: Gửi yêu cầu bằng invitation code hợp lệ | E8: P1 | F8: Functional | G8: API + UI/E2E | H8: GET /api/v1/common/companies/search/ GET|POST /api/v1/common/join-requests/ POST /api/v1/common/join-requests/{id}/cancel/ GET /api/v1/common/company-join-requests/ POST /api/v1/common/company-join-requests/{id}/decide/ | I8: Có U2 (applicant), U7 (admin C1), C1 ACTIVE và Permission phù hợp theo từng test case. | J8: applicant=U2; admin=U7; company=C1; message=Xin tham gia doanh nghiệp | K8: 1. Chuẩn bị dữ liệu đúng mục 'Điều kiện trước' và ghi lại các ID ban đầu. 2. Đăng nhập bằng đúng actor/role và chọn company/branch theo điều kiện trước. 3. Thực hiện kịch bản: Gửi yêu cầu bằng invitation code hợp lệ. 4. Ghi lại HTTP status, response body và thông báo/điều hướng trên UI (nếu có). 5. Kiểm tra request, membership, quyết định, thông báo và quyền của cả applicant/admin. 6. So sánh toàn bộ kết quả với cột 'Kết quả mong đợi' và đính kèm evidence nếu Fail/Blocked. | L8: Chọn đúng doanh nghiệp; tăng use count; auto-approve nếu invitation cấu hình như vậy | M8: Không có pending request/membership/notification trùng; decided_by/at chính xác. | O8: Not Run | U8: Candidate
A9: 6 | B9: COM02-06 | C9: UC-COM-02 | D9: Invitation hết hạn/bị thu hồi/sai/vượt max use | E9: P0 | F9: Functional | G9: API + UI/E2E | H9: GET /api/v1/common/companies/search/ GET|POST /api/v1/common/join-requests/ POST /api/v1/common/join-requests/{id}/cancel/ GET /api/v1/common/company-join-requests/ POST /api/v1/common/company-join-requests/{id}/decide/ | I9: Có U2 (applicant), U7 (admin C1), C1 ACTIVE và Permission phù hợp theo từng test case. | J9: applicant=U2; admin=U7; company=C1; message=Xin tham gia doanh nghiệp Bổ sung: Điều chỉnh expires_at về quá khứ bằng fixture/admin test; AI stub hỗ trợ success, timeout, HTTP 500, invalid JSON và oversized response | K9: 1. Chuẩn bị dữ liệu đúng mục 'Điều kiện trước' và ghi lại các ID ban đầu. 2. Đăng nhập bằng đúng actor/role và chọn company/branch theo điều kiện trước. 3. Thực hiện kịch bản: Invitation hết hạn/bị thu hồi/sai/vượt max use. 4. Ghi lại HTTP status, response body và thông báo/điều hướng trên UI (nếu có). 5. Kiểm tra request, membership, quyết định, thông báo và quyền của cả applicant/admin. 6. So sánh toàn bộ kết quả với cột 'Kết quả mong đợi' và đính kèm evidence nếu Fail/Blocked. | L9: 400; không tạo membership hoặc tăng use count sai | M9: Không có pending request/membership/notification trùng; decided_by/at chính xác. | O9: Not Run | U9: Candidate
A10: 7 | B10: COM02-07 | C10: UC-COM-02 | D10: User đã là thành viên ACTIVE của C1 vẫn gửi yêu cầu | E10: P0 | F10: Functional | G10: API + UI/E2E | H10: GET /api/v1/common/companies/search/ GET|POST /api/v1/common/join-requests/ POST /api/v1/common/join-requests/{id}/cancel/ GET /api/v1/common/company-join-requests/ POST /api/v1/common/company-join-requests/{id}/decide/ | I10: Có U2 (applicant), U7 (admin C1), C1 ACTIVE và Permission phù hợp theo từng test case. | J10: applicant=U2; admin=U7; company=C1; message=Xin tham gia doanh nghiệp | K10: 1. Chuẩn bị dữ liệu đúng mục 'Điều kiện trước' và ghi lại các ID ban đầu. 2. Đăng nhập bằng đúng actor/role và chọn company/branch theo điều kiện trước. 3. Thực hiện kịch bản: User đã là thành viên ACTIVE của C1 vẫn gửi yêu cầu. 4. Ghi lại HTTP status, response body và thông báo/điều hướng trên UI (nếu có). 5. Kiểm tra request, membership, quyết định, thông báo và quyền của cả applicant/admin. 6. So sánh toàn bộ kết quả với cột 'Kết quả mong đợi' và đính kèm evidence nếu Fail/Blocked. | L10: Bị từ chối; không tạo yêu cầu trùng | M10: Không có pending request/membership/notification trùng; decided_by/at chính xác. | O10: Not Run | U10: Candidate
A11: 8 | B11: COM02-08 | C11: UC-COM-02 | D11: Requester hủy yêu cầu PENDING của chính mình | E11: P1 | F11: Functional | G11: API + UI/E2E | H11: GET /api/v1/common/companies/search/ GET|POST /api/v1/common/join-requests/ POST /api/v1/common/join-requests/{id}/cancel/ GET /api/v1/common/company-join-requests/ POST /api/v1/common/company-join-requests/{id}/decide/ | I11: Có U2 (applicant), U7 (admin C1), C1 ACTIVE và Permission phù hợp theo từng test case. | J11: applicant=U2; admin=U7; company=C1; message=Xin tham gia doanh nghiệp | K11: 1. Chuẩn bị dữ liệu đúng mục 'Điều kiện trước' và ghi lại các ID ban đầu. 2. Đăng nhập bằng đúng actor/role và chọn company/branch theo điều kiện trước. 3. Thực hiện kịch bản: Requester hủy yêu cầu PENDING của chính mình. 4. Ghi lại HTTP status, response body và thông báo/điều hướng trên UI (nếu có). 5. Kiểm tra request, membership, quyết định, thông báo và quyền của cả applicant/admin. 6. So sánh toàn bộ kết quả với cột 'Kết quả mong đợi' và đính kèm evidence nếu Fail/Blocked. | L11: Status CANCELLED, ghi thời điểm/lịch sử phù hợp; admin không thể duyệt sau đó | M11: Không có pending request/membership/notification trùng; decided_by/at chính xác. | O11: Not Run | U11: Candidate
A12: 9 | B12: COM02-09 | C12: UC-COM-02 | D12: User khác hủy hoặc xem chi tiết yêu cầu không thuộc mình | E12: P0 | F12: Security/Authorization | G12: API + Integration | H12: GET /api/v1/common/companies/search/ GET|POST /api/v1/common/join-requests/ POST /api/v1/common/join-requests/{id}/cancel/ GET /api/v1/common/company-join-requests/ POST /api/v1/common/company-join-requests/{id}/decide/ | I12: Có U2 (applicant), U7 (admin C1), C1 ACTIVE và Permission phù hợp theo từng test case. | J12: applicant=U2; admin=U7; company=C1; message=Xin tham gia doanh nghiệp | K12: 1. Chuẩn bị dữ liệu đúng mục 'Điều kiện trước' và ghi lại các ID ban đầu. 2. Đăng nhập bằng đúng actor/role và chọn company/branch theo điều kiện trước. 3. Thực hiện kịch bản: User khác hủy hoặc xem chi tiết yêu cầu không thuộc mình. 4. Ghi lại HTTP status, response body và thông báo/điều hướng trên UI (nếu có). 5. Kiểm tra request, membership, quyết định, thông báo và quyền của cả applicant/admin. 6. So sánh toàn bộ kết quả với cột 'Kết quả mong đợi' và đính kèm evidence nếu Fail/Blocked. | L12: 404/403; không lộ nội dung yêu cầu | M12: Không có pending request/membership/notification trùng; decided_by/at chính xác. | O12: Not Run | U12: Candidate
